Workbook
Name _2Excel_BuiltIn_Print_Titles_2_1: (#REF!,#REF!)
Name _2Excel_BuiltIn_Print_Titles_2_1: (#REF!,#REF!)
Name _2Excel_BuiltIn_Print_Titles_2_1: (#REF!,#REF!)
Name _2Excel_BuiltIn_Print_Titles_2_1: (#REF!,#REF!)
Name _2Excel_BuiltIn_Print_Titles_2_1: (#REF!,#REF!)
Name _2Excel_BuiltIn_Print_Titles_2_1: (#REF!,#REF!)
Name _2Excel_BuiltIn_Print_Titles_2_1: (#REF!,#REF!)
Name _2Excel_BuiltIn_Print_Titles_2_1: (#REF!,#REF!)
Name _2Excel_BuiltIn_Print_Titles_2_1: (#REF!,#REF!)
Name _2Excel_BuiltIn_Print_Titles_2_1: (#REF!,#REF!)
Name _2Excel_BuiltIn_Print_Titles_2_1: (#REF!,#REF!)
Name _2Excel_BuiltIn_Print_Titles_2_1: (#REF!,#REF!)
Name _2Excel_BuiltIn_Print_Titles_2_1: (#REF!,#REF!)
Name _2Excel_BuiltIn_Print_Titles_2_1: (#REF!,#REF!)
Name _2Excel_BuiltIn_Print_Titles_2_1: (#REF!,#REF!)
Name _2Excel_BuiltIn_Print_Titles_2_1: (#REF!,#REF!)
Name _2Excel_BuiltIn_Print_Titles_2_1: (#REF!,#REF!)
Name _2Excel_BuiltIn_Print_Titles_2_1: (#REF!,#REF!)
Name _2Excel_BuiltIn_Print_Titles_2_1: (#REF!,#REF!)
Name _2Excel_BuiltIn_Print_Titles_2_1: (#REF!,#REF!)
Name _2Excel_BuiltIn_Print_Titles_2_1: (#REF!,#REF!)
Name _2Excel_BuiltIn_Print_Titles_2_1: (#REF!,#REF!)
Name _2Excel_BuiltIn_Print_Titles_2_1: (#REF!,#REF!)
Name _2Excel_BuiltIn_Print_Titles_2_1: (#REF!,#REF!)
Name _2Excel_BuiltIn_Print_Titles_2_1: (#REF!,#REF!)
Name _2Excel_BuiltIn_Print_Titles_2_1: (#REF!,#REF!)
Name _2Excel_BuiltIn_Print_Titles_2_1: (#REF!,#REF!)
Name _2Excel_BuiltIn_Print_Titles_2_1: (#REF!,#REF!)
Name _IN002010: #REF!
Name _IN002010: #REF!
Name _IN002010: #REF!
Name _IN002010: #REF!
Name _IN002010: #REF!
Name _IN002010: #REF!
Name _IN002010: #REF!
Name _IN002010: #REF!
Name _IN002010: #REF!
Name _IN002010: #REF!
Name _IN002010: #REF!
Name _IN002010: #REF!
Name _IN002010: #REF!
Name _IN002010: #REF!
Name _IN002010: #REF!
Name _IN002010: #REF!
Name _IN002010: #REF!
Name _IN002010: #REF!
Name _IN002010: #REF!
Name _IN002010: #REF!
Name _IN002010: #REF!
Name _IN002010: #REF!
Name _IN002010: #REF!
Name _IN002010: #REF!
Name _IN002010: #REF!
Name _IN002010: #REF!
Name _IN002010: #REF!
Name _IN002010: #REF!
Name _IN002040: #REF!
Name _IN002040: #REF!
Name _IN002040: #REF!
Name _IN002040: #REF!

Sheet Pricing Structure
B2: PRICING STRUCTURE | L2: Approved | T2: Approved | AB2: Approved
F3: GSS LOKAL 40 | N3: IIP LOKAL 40 | V3: IHAG LOKAL 40
B5: General Info | C5: Type | F5: (Existing) | H5: Scenario 1 | J5: Scenario 2 | L5: Scenario 3 | N5: (Existing) | P5: Scenario 1 | R5: Scenario 2 | T5: Scenario 3 | V5: (Existing) | X5: Scenario 1 | Z5: Scenario 2 | AB5: Scenario 3
C6: Flavour Matcode | F6: GSS LOKAL 40 | H6: =F6 -> GSS LOKAL 40 | J6: =F6 -> GSS LOKAL 40 | L6: =F6 -> GSS LOKAL 40 | N6: IIP LOKAL 40 | P6: =N6 -> IIP LOKAL 40 | R6: =N6 -> IIP LOKAL 40 | T6: =N6 -> IIP LOKAL 40 | V6: IHAG LOKAL 40 | X6: =V6 -> IHAG LOKAL 40 | Z6: =V6 -> IHAG LOKAL 40 | AB6: =V6 -> IHAG LOKAL 40
C7: CIF | F7: CURRENT (CIF $5.6/crtn) | N7: CURRENT (CIF $5.6/crtn) | V7: CURRENT (CIF $5.6/crtn)
C8: Disc | F8: TP $0.47/ctn, MF $1.1/ctn | H8: TP $0.47/ctn, MF $1.1/ctn | J8: TP $0.47/ctn, MF $0.90/ctn | L8: TP $0.40/ctn, MF $1/ctn | N8: TP $0.47/ctn, MF $0.9/ctn | P8: TP $0.47/ctn, MF $0.9/ctn | R8: TP $0.47/ctn, MF $0.60/ctn | T8: TP $0.40/ctn, MF $0.75/ctn | V8: TP $0.47/ctn | X8: TP $0.47/ctn | Z8: TP $0.47/ctn | AB8: TP $0.40/ctn
C9: Content | F9: 40 | G9: =+F9 -> 40 | H9: 40 | I9: =+H9 -> 40 | J9: 40 | K9: =+J9 -> 40 | L9: 40 | M9: =+L9 -> 40 | N9: 40 | O9: =+N9 -> 40 | P9: 40 | Q9: =+P9 -> 40 | R9: 40 | S9: =+R9 -> 40 | T9: 40 | U9: =+T9 -> 40 | V9: 40 | W9: =+V9 -> 40 | X9: 40 | Y9: =+X9 -> 40 | Z9: 40 | AA9: =+Z9 -> 40 | AB9: 40 | AC9: =+AB9 -> 40
C10: Currency | F10: KHR | G10: USD | H10: =F10 -> KHR | I10: USD | J10: =H10 -> KHR | K10: USD | L10: =J10 -> KHR | M10: USD | N10: KHR | O10: USD | P10: =N10 -> KHR | Q10: USD | R10: =P10 -> KHR | S10: USD | T10: =R10 -> KHR | U10: USD | V10: KHR | W10: USD | X10: =V10 -> KHR | Y10: USD | Z10: =X10 -> KHR | AA10: USD | AB10: =Z10 -> KHR | AC10: USD
C11: Exchange rate per- | D11: 44217 | F11: 4080 | H11: =F11 -> 4080 | J11: =H11 -> 4080 | L11: =J11 -> 4080 | N11: 4080 | P11: =N11 -> 4080 | R11: =P11 -> 4080 | T11: =R11 -> 4080 | V11: 4080 | X11: =V11 -> 4080 | Z11: =X11 -> 4080 | AB11: =Z11 -> 4080
B14: Consumer | C14: CBP with VAT - per pack | F14: 1000 | G14: =+F14/$H$11 -> 0.24509804 | H14: 1000 | I14: =+H14/$H$11 -> 0.24509804 | J14: =H14 -> 1000 | K14: =+J14/$H$11 -> 0.24509804 | L14: =J14 -> 1000 | M14: =+L14/$H$11 -> 0.24509804 | N14: 1000 | O14: =+N14/$H$11 -> 0.24509804 | P14: 1000 | Q14: =+P14/$H$11 -> 0.24509804 | R14: =P14 -> 1000 | S14: =+R14/$H$11 -> 0.24509804 | T14: =R14 -> 1000 | U14: =+T14/$H$11 -> 0.24509804 | V14: 1000 | W14: =+V14/$H$11 -> 0.24509804 | X14: 1000 | Y14: =+X14/$H$11 -> 0.24509804 | Z14: =X14 -> 1000 | AA14: =+Z14/$H$11 -> 0.24509804 | AB14: =Z14 -> 1000 | AC14: =+AB14/$H$11 -> 0.24509804
C15: CBP with VAT - per carton | F15: =+F14*F9 -> 40000 | G15: =+G14*G9 -> 9.8039216 | H15: =+H14*H9 -> 40000 | I15: =+I14*I9 -> 9.8039216 | J15: =+J14*J9 -> 40000 | K15: =+K14*K9 -> 9.8039216 | L15: =+L14*L9 -> 40000 | M15: =+M14*M9 -> 9.8039216 | ... AC15: =+AC14*AC9 -> 9.8039216
C16: VAT | D16: - per pack | F16: 0 | G16: 0 | H16: 0 | I16: 0 | J16: 0 | K16: 0 | L16: 0 | M16: 0 | N16: 0 | O16: 0 | P16: 0 | Q16: 0 | R16: 0 | S16: 0 | T16: 0 | U16: 0 | V16: 0 | W16: 0 | X16: 0 | Y16: 0 | Z16: 0 | AA16: 0 | AB16: 0 | AC16: 0
C17: VAT % | F17: 0 | G17: 0 | H17: 0 | I17: 0 | J17: 0 | K17: 0 | L17: 0 | M17: 0 | N17: 0 | O17: 0 | P17: 0 | Q17: 0 | R17: 0 | S17: 0 | T17: 0 | U17: 0 | V17: 0 | W17: 0 | X17: 0 | Y17: 0 | Z17: 0 | AA17: 0 | AB17: 0 | AC17: 0
C18: CBP without VAT - per pack | F18: =F14-F16 -> 1000 | G18: =G14-G16 -> 0.24509804 | H18: =H14-H16 -> 1000 | I18: =I14-I16 -> 0.24509804 | J18: =J14-J16 -> 1000 | K18: =K14-K16 -> 0.24509804 | L18: =L14-L16 -> 1000 | M18: =M14-M16 -> 0.24509804 | ... AC18: =AC14-AC16 -> 0.24509804
C19: CBP without VAT - per carton | F19: =1/(1+F17)*F15 -> 40000 | G19: =1/(1+G17)*G15 -> 9.8039216 | H19: =1/(1+H17)*H15 -> 40000 | I19: =1/(1+I17)*I15 -> 9.8039216 | J19: =1/(1+J17)*J15 -> 40000 | K19: =1/(1+K17)*K15 -> 9.8039216 | L19: =1/(1+L17)*L15 -> 40000 | M19: =1/(1+M17)*M15 -> 9.8039216 | ... AC19: =1/(1+AC17)*AC15 -> 9.8039216
B21: Retailer
C22: Retailers' margin (%) | F22: =F23/F19 -> 0.19 | G22: =G23/G19 -> 0.19 | H22: =H23/H19 -> 0.19 | I22: =I23/I19 -> 0.19 | J22: =J23/J19 -> 0.19 | K22: =K23/K19 -> 0.19 | L22: =L23/L19 -> 0.19 | M22: =M23/M19 -> 0.19 | ... AC22: =AC23/AC19 -> 0.19
C23: Retailers' margin | F23: =F19-F25 -> 7600 | G23: =G19-G25 -> 1.8627451 | H23: =H19-H25 -> 7600 | I23: =I19-I25 -> 1.8627451 | J23: =J19-J25 -> 7600 | K23: =K19-K25 -> 1.8627451 | L23: =L19-L25 -> 7600 | M23: =M19-M25 -> 1.8627451 | ... AC23: =AC19-AC25 -> 1.8627451
C24: Retailers' Buying Price per carton +VAT | F24: =F25 -> 32400 | G24: =G25 -> 7.9411765 | H24: =H25 -> 32400 | I24: =I25 -> 7.9411765 | J24: =J25 -> 32400 | K24: =K25 -> 7.9411765 | L24: =L25 -> 32400 | M24: =M25 -> 7.9411765 | ... AC24: =AC25 -> 7.9411765
C25: Retailers' Buying Price (ctn) | F25: 32400 | G25: =+F25/$H$11 -> 7.9411765 | H25: =F25 -> 32400 | I25: =+H25/$H$11 -> 7.9411765 | J25: =H25 -> 32400 | K25: =+J25/$H$11 -> 7.9411765 | L25: =J25 -> 32400 | M25: =+L25/$H$11 -> 7.9411765 | N25: 32400 | O25: =+N25/$H$11 -> 7.9411765 | P25: =N25 -> 32400 | Q25: =+P25/$H$11 -> 7.9411765 | R25: =P25 -> 32400 | S25: =+R25/$H$11 -> 7.9411765 | T25: =R25 -> 32400 | U25: =+T25/$H$11 -> 7.9411765 | V25: 32400 | W25: =+V25/$H$11 -> 7.9411765 | X25: =V25 -> 32400 | Y25: =+X25/$H$11 -> 7.9411765 | Z25: =X25 -> 32400 | AA25: =+Z25/$H$11 -> 7.9411765 | AB25: =Z25 -> 32400 | AC25: =+AB25/$H$11 -> 7.9411765
B27: Wholesaler
C28: Wholesalers' margin (%) | F28: =F29/F25 -> 0.071541433 | G28: =G29/G25 -> 0.071541433 | H28: =H29/H25 -> 0.071541433 | I28: =I29/I25 -> 0.071541433 | J28: =J29/J25 -> 0.071541433 | K28: =K29/K25 -> 0.071541433 | L28: =L29/L25 -> 0.071541433 | M28: =M29/M25 -> 0.071541433 | ... AC28: =AC29/AC25 -> 0.071541433
C29: Wholesalers' margin | F29: =F25-F31 -> 2317.9424 | G29: =G25-G31 -> 0.56812315 | H29: =H25-H31 -> 2317.9424 | I29: =I25-I31 -> 0.56812315 | J29: =J25-J31 -> 2317.9424 | K29: =K25-K31 -> 0.56812315 | L29: =L25-L31 -> 2317.9424 | M29: =M25-M31 -> 0.56812315 | ... AC29: =AC25-AC31 -> 0.56812315
C30: Wholesalers' Buying Price per carton +VAT | F30: =+F31 -> 30082.058 | G30: =G31 -> 7.3730533 | H30: =+H31 -> 30082.058 | I30: =I31 -> 7.3730533 | J30: =+J31 -> 30082.058 | K30: =K31 -> 7.3730533 | L30: =+L31 -> 30082.058 | M30: =M31 -> 7.3730533 | N30: =+N31 -> 30082.058 | O30: =O31 -> 7.3730533 | P30: =+P31 -> 30082.058 | Q30: =Q31 -> 7.3730533 | R30: =+R31 -> 30082.058 | S30: =S31 -> 7.3730533 | T30: =+T31 -> 30082.058 | U30: =U31 -> 7.3730533 | V30: =+V31 -> 30082.058 | W30: =W31 -> 7.3730533 | X30: =+X31 -> 30082.058 | Y30: =Y31 -> 7.3730533 | Z30: =+Z31 -> 30082.058 | AA30: =AA31 -> 7.3730533 | AB30: =+AB31 -> 30082.058 | AC30: =AC31 -> 7.3730533
C31: Wholesalers' Buying Price (ctn) | F31: 30082.058 | G31: =+F31/$H$11 -> 7.3730533 | H31: 30082.058 | I31: =+H31/$H$11 -> 7.3730533 | J31: 30082.058 | K31: =+J31/$H$11 -> 7.3730533 | L31: 30082.058 | M31: =+L31/$H$11 -> 7.3730533 | N31: 30082.058 | O31: =+N31/$H$11 -> 7.3730533 | P31: 30082.058 | Q31: =+P31/$H$11 -> 7.3730533 | R31: 30082.058 | S31: =+R31/$H$11 -> 7.3730533 | T31: 30082.058 | U31: =+T31/$H$11 -> 7.3730533 | V31: 30082.058 | W31: =+V31/$H$11 -> 7.3730533 | X31: 30082.058 | Y31: =+X31/$H$11 -> 7.3730533 | Z31: 30082.058 | AA31: =+Z31/$H$11 -> 7.3730533 | AB31: 30082.058 | AC31: =+AB31/$H$11 -> 7.3730533
B33: Distributor
C34: Distributors' margin (%) | F34: =+F35/F31 -> 0.13332703 | G34: =+G35/G31 -> 0.13332703 | H34: =+H35/H31 -> 0.1098293 | I34: =+I35/I31 -> 0.1098293 | J34: =+J35/J31 -> 0.13332703 | K34: =+K35/K31 -> 0.13332703 | L34: =+L35/L31 -> 0.12236142 | M34: =+M35/M31 -> 0.12236142 | ... AC34: =+AC35/AC31 -> 0.11664246
C35: Distributors' margin | F35: =+F31-F36 -> 4010.7513 | G35: =+G31-G36 -> 0.98302729 | H35: =+H31-H36 -> 3303.8913 | I35: =+I31-I36 -> 0.80977729 | J35: =+J31-J36 -> 4010.7513 | K35: =+K31-K36 -> 0.98302729 | L35: =+L31-L36 -> 3680.8833 | M35: =+M31-M36 -> 0.90217729 | ... AC35: =+AC31-AC36 -> 0.86001107
C36: Distributors' Buying Price | F36: =+G40*F11 -> 26071.306 | G36: =+G40 -> 6.390026 | H36: =+I40*H11 -> 26778.166 | I36: =+I40 -> 6.563276 | J36: =+K40*J11 -> 26071.306 | K36: =+K40 -> 6.390026 | L36: =+M40*L11 -> 26401.174 | M36: =+M40 -> 6.470876 | N36: =+O40*N11 -> 26010.612 | O36: =+O40 -> 6.37515 | P36: =+Q40*P11 -> 26717.472 | Q36: =+Q40 -> 6.5484 | R36: =+S40*R11 -> 26010.612 | S36: =+S40 -> 6.37515 | T36: =+U40*T11 -> 26340.48 | U36: =+U40 -> 6.456 | V36: =+W40*V11 -> 26243.344 | W36: =+W40 -> 6.4321923 | X36: =+Y40*X11 -> 26950.204 | Y36: =+Y40 -> 6.6054423 | Z36: =+AA40*Z11 -> 26243.344 | AA36: =+AA40 -> 6.4321923 | AB36: =+AC40*AB11 -> 26573.212 | AC36: =+AC40 -> 6.5130423
C37: Additional cost In Land trucking | F37: 0 | H37: 0 | J37: 0 | L37: 0 | N37: 0 | P37: 0 | R37: 0 | T37: 0 | V37: 0 | X37: 0 | Z37: 0 | AB37: 0
B38: Importer / Distributor
C39: Landed Cost in pack | E39: USD | F39: =+F40/F9 -> 651.78266 | G39: =+G40/G9 -> 0.15975065 | H39: =+H40/H9 -> 669.45416 | I39: =+I40/I9 -> 0.1640819 | J39: =+J40/J9 -> 651.78266 | K39: =+K40/K9 -> 0.15975065 | L39: =+L40/L9 -> 660.02936 | M39: =+M40/M9 -> 0.1617719 | ... AC39: =+AC40/AC9 -> 0.16282606
C40: Landed Cost in carton | E40: USD | F40: =+G40*F11 -> 26071.306 | G40: =+G41+G43+G47+G45 -> 6.390026 | H40: =+I40*H11 -> 26778.166 | I40: =+I41+I43+I47+I45 -> 6.563276 | J40: =+K40*J11 -> 26071.306 | K40: =+K41+K43+K47+K45 -> 6.390026 | L40: =+M40*L11 -> 26401.174 | M40: =+M41+M43+M47+M45 -> 6.470876 | N40: =+O40*N11 -> 26010.612 | O40: =+O41+O43+O47+O45 -> 6.37515 | P40: =+Q40*P11 -> 26717.472 | Q40: =+Q41+Q43+Q47+Q45 -> 6.5484 | R40: =+S40*R11 -> 26010.612 | S40: =+S41+S43+S47+S45 -> 6.37515 | T40: =+U40*T11 -> 26340.48 | U40: =+U41+U43+U47+U45 -> 6.456 | V40: =+W40*V11 -> 26243.344 | W40: =+W41+W43+W47+W45 -> 6.4321923 | X40: =+Y40*X11 -> 26950.204 | Y40: =+Y41+Y43+Y47+Y45 -> 6.6054423 | Z40: =+AA40*Z11 -> 26243.344 | AA40: =+AA41+AA43+AA47+AA45 -> 6.4321923 | AB40: =+AC40*AB11 -> 26573.212 | AC40: =+AC41+AC43+AC47+AC45 -> 6.5130423
C41: Import duty rate - 5% | E41: USD | G41: =+G42*G47 -> 0.2565 | I41: =+I42*I47 -> 0.264 | K41: =+K42*K47 -> 0.2565 | M41: =+M42*M47 -> 0.26 | O41: =+O42*O47 -> 0.2565 | Q41: =+Q42*Q47 -> 0.264 | S41: =+S42*S47 -> 0.2565 | U41: =+U42*U47 -> 0.26 | W41: =+W42*W47 -> 0.2565 | Y41: =+Y42*Y47 -> 0.264 | AA41: =+AA42*AA47 -> 0.2565 | AC41: =+AC42*AC47 -> 0.26
C42: Import duty % | G42: 0.05 | I42: =G42 -> 0.05 | K42: =I42 -> 0.05 | M42: =K42 -> 0.05 | O42: 0.05 | Q42: =O42 -> 0.05 | S42: =Q42 -> 0.05 | U42: =S42 -> 0.05 | W42: 0.05 | Y42: =W42 -> 0.05 | AA42: =Y42 -> 0.05 | AC42: =AA42 -> 0.05
C43: Other charges - Clearance cost | E43: USD | G43: =$D$44/G56 -> 0.46487603 | I43: =$D$44/I56 -> 0.46487603 | K43: =$D$44/K56 -> 0.46487603 | M43: =$D$44/M56 -> 0.46487603 | O43: =$D$44/O56 -> 0.45 | Q43: =$D$44/Q56 -> 0.45 | S43: =$D$44/S56 -> 0.45 | U43: =$D$44/U56 -> 0.45 | W43: =$D$44/W56 -> 0.50704225 | Y43: =$D$44/Y56 -> 0.50704225 | AA43: =$D$44/AA56 -> 0.50704225 | AC43: =$D$44/AC56 -> 0.50704225
C44: Other charges % | D44: 1800 | G44: =G43/G47 -> 0.09061911 | I44: =I43/I47 -> 0.088044703 | K44: =K43/K47 -> 0.09061911 | M44: =M43/M47 -> 0.089399237 | O44: =O43/O47 -> 0.087719298 | Q44: =Q43/Q47 -> 0.085227273 | S44: =S43/S47 -> 0.087719298 | U44: =U43/U47 -> 0.086538462 | W44: =W43/W47 -> 0.098838646 | Y44: =Y43/Y47 -> 0.09603073 | AA44: =AA43/AA47 -> 0.098838646 | AC44: =AC43/AC47 -> 0.097508126
C45: VAT in | G45: =(G46*(G47+G41)) -> 0.53865 | I45: =(I46*(I47+I41)) -> 0.5544 | K45: =(K46*(K47+K41)) -> 0.53865 | M45: =(M46*(M47+M41)) -> 0.546 | O45: =(O46*(O47+O41)) -> 0.53865 | Q45: =(Q46*(Q47+Q41)) -> 0.5544 | S45: =(S46*(S47+S41)) -> 0.53865 | U45: =(U46*(U47+U41)) -> 0.546 | W45: =(W46*(W47+W41)) -> 0.53865 | Y45: =(Y46*(Y47+Y41)) -> 0.5544 | AA45: =(AA46*(AA47+AA41)) -> 0.53865 | AC45: =(AC46*(AC47+AC41)) -> 0.546
C46: VAT in (% from CIF + Import duty) | G46: 0.1 | I46: 0.1 | K46: 0.1 | M46: 0.1 | O46: 0.1 | Q46: 0.1 | S46: 0.1 | U46: 0.1 | W46: 0.1 | Y46: 0.1 | AA46: 0.1 | AC46: 0.1
C47: CIF price after support & Freight Surcharge | E47: USD | G47: =G51-G48+G49 -> 5.13 | I47: =I51-I48+I49 -> 5.28 | K47: =K51-K48+K49 -> 5.13 | M47: =M51-M48+M49 -> 5.2 | O47: =O51-O48+O49 -> 5.13 | Q47: =Q51-Q48+Q49 -> 5.28 | S47: =S51-S48+S49 -> 5.13 | U47: =U51-U48+U49 -> 5.2 | W47: =W51-W48+W49 -> 5.13 | Y47: =Y51-Y48+Y49 -> 5.28 | AA47: =AA51-AA48+AA49 -> 5.13 | AC47: =AC51-AC48+AC49 -> 5.2
...

Sheet All SKU Pricing Structure
B2: PRICING STRUCTURE | F2: =F3 -> GSS LOKAL 40 | H2: =H3 -> IIP LOKAL 40 | J2: =J3 -> IHAG LOKAL 40 | L2: =L3 -> GPD LOKAL 40 | N2: =N3 -> CGSS MA 12 | P2: =P3 -> PMAD LOKAL 12 | R2: =R3 -> PMAJ LOKAL 24
F3: GSS LOKAL 40 | H3: IIP LOKAL 40 | J3: IHAG LOKAL 40 | L3: GPD LOKAL 40 | N3: CGSS MA 12 | P3: PMAD LOKAL 12 | R3: PMAJ LOKAL 24
B5: General Info | C5: Type
C6: Flavour Matcode | F6: 100493 | H6: 141884 | J6: 199660 | L6: 100491 | N6: 123630 | P6: 184763 | R6: 136915
C7: CIF | F7: =G51 -> 5.6 | H7: =I51 -> 5.6 | J7: =K51 -> 5.6 | L7: =M51 -> 5.6 | N7: =O51 -> 4.6 | P7: =Q51 -> 4.25 | R7: =S51 -> 6.3
C8: Disc | F8: TP $0.40/ctn | H8: TP $0.40/ctn | J8: TP $0.40/ctn | L8: TP $0.40/ctn | N8: TP $0.90/ctn | P8: TP $0.90/ctn | R8: TP $1.80/ctn
C9: Content | F9: =RIGHT(F2,2) -> 40 | G9: =+F9 -> 40 | H9: =RIGHT(H2,2) -> 40 | I9: =+H9 -> 40 | J9: =RIGHT(J2,2) -> 40 | K9: =+J9 -> 40 | L9: =RIGHT(L2,2) -> 40 | M9: =+L9 -> 40 | N9: =RIGHT(N2,2) -> 12 | O9: =+N9 -> 12 | P9: =RIGHT(P2,2) -> 12 | Q9: =+P9 -> 12 | R9: =RIGHT(R2,2) -> 24 | S9: =+R9 -> 24
C10: Currency | F10: KHR | G10: USD | H10: KHR | I10: USD | J10: KHR | K10: USD | L10: KHR | M10: USD | N10: KHR | O10: USD | P10: KHR | Q10: USD | R10: KHR | S10: USD
C11: Exchange rate per- | D11: 44407 | F11: 4068.66 | H11: 4068.66 | J11: 4068.66 | L11: 4068.66 | N11: 4068.66 | P11: 4068.66 | R11: 4068.66
B14: Consumer | C14: CBP with VAT - per pack | F14: 1000 | G14: =+F14/F11 -> 0.24578117 | H14: 1000 | I14: =+H14/H11 -> 0.24578117 | J14: 1000 | K14: =+J14/J11 -> 0.24578117 | L14: 1000 | M14: =+L14/L11 -> 0.24578117 | N14: 3250 | O14: =+N14/N11 -> 0.79878879 | P14: 2400 | Q14: =+P14/P11 -> 0.5898748 | R14: 2000 | S14: =+R14/R11 -> 0.49156233
C15: CBP with VAT - per carton | F15: =+F14*F9 -> 40000 | G15: =+G14*G9 -> 9.8312467 | H15: =+H14*H9 -> 40000 | I15: =+I14*I9 -> 9.8312467 | J15: =+J14*J9 -> 40000 | K15: =+K14*K9 -> 9.8312467 | L15: =+L14*L9 -> 40000 | M15: =+M14*M9 -> 9.8312467 | ... S15: =+S14*S9 -> 11.797496
C16: VAT | D16: - per pack | F16: 0 | G16: 0 | H16: 0 | I16: 0 | J16: 0 | K16: 0 | L16: 0 | M16: 0 | N16: 0 | O16: 0 | P16: 0 | Q16: 0 | R16: 0 | S16: 0
C17: VAT % | F17: 0 | G17: 0 | H17: 0 | I17: 0 | J17: 0 | K17: 0 | L17: 0 | M17: 0 | N17: 0 | O17: 0 | P17: 0 | Q17: 0 | R17: 0 | S17: 0
C18: CBP without VAT - per pack | F18: =F14-F16 -> 1000 | G18: =G14-G16 -> 0.24578117 | H18: =H14-H16 -> 1000 | I18: =I14-I16 -> 0.24578117 | J18: =J14-J16 -> 1000 | K18: =K14-K16 -> 0.24578117 | L18: =L14-L16 -> 1000 | M18: =M14-M16 -> 0.24578117 | ... S18: =S14-S16 -> 0.49156233
C19: CBP without VAT - per carton | F19: =1/(1+F17)*F15 -> 40000 | G19: =1/(1+G17)*G15 -> 9.8312467 | H19: =1/(1+H17)*H15 -> 40000 | I19: =1/(1+I17)*I15 -> 9.8312467 | J19: =1/(1+J17)*J15 -> 40000 | K19: =1/(1+K17)*K15 -> 9.8312467 | L19: =1/(1+L17)*L15 -> 40000 | M19: =1/(1+M17)*M15 -> 9.8312467 | ... S19: =1/(1+S17)*S15 -> 11.797496
B21: Retailer
C22: Retailers' margin (%) | F22: =F23/F19 -> 0.19 | G22: =G23/G19 -> 0.19 | H22: =H23/H19 -> 0.19 | I22: =I23/I19 -> 0.19 | J22: =J23/J19 -> 0.19 | K22: =K23/K19 -> 0.19 | L22: =L23/L19 -> 0.19 | M22: =M23/M19 -> 0.19 | ... S22: =S23/S19 -> 0.240625
C23: Retailers' margin | F23: =F19-F25 -> 7600 | G23: =G19-G25 -> 1.8679369 | H23: =H19-H25 -> 7600 | I23: =I19-I25 -> 1.8679369 | J23: =J19-J25 -> 7600 | K23: =K19-K25 -> 1.8679369 | L23: =L19-L25 -> 7600 | M23: =M19-M25 -> 1.8679369 | ... S23: =S19-S25 -> 2.8387725
C24: Retailers' Buying Price per carton +VAT | F24: =F25 -> 32400 | G24: =G25 -> 7.9633098 | H24: =H25 -> 32400 | I24: =I25 -> 7.9633098 | J24: =J25 -> 32400 | K24: =K25 -> 7.9633098 | L24: =L25 -> 32400 | M24: =M25 -> 7.9633098 | ... S24: =S25 -> 8.9587235
C25: Retailers' Buying Price (ctn) | F25: 32400 | G25: =+F25/F11 -> 7.9633098 | H25: 32400 | I25: =+H25/H11 -> 7.9633098 | J25: 32400 | K25: =+J25/J11 -> 7.9633098 | L25: 32400 | M25: =+L25/L11 -> 7.9633098 | N25: 25110 | O25: =+N25/N11 -> 6.1715651 | P25: 20400 | Q25: =+P25/P11 -> 5.0139358 | R25: 36450 | S25: =+R25/R11 -> 8.9587235
B27: Wholesaler
C28: Wholesalers' margin (%) | F28: =F29/F25 -> 0.071541433 | G28: =G29/G25 -> 0.071541433 | H28: =H29/H25 -> 0.071541433 | I28: =I29/I25 -> 0.071541433 | J28: =J29/J25 -> 0.071541433 | K28: =K29/K25 -> 0.071541433 | L28: =L29/L25 -> 0.071541433 | M28: =M29/M25 -> 0.071541433 | ... S28: =S29/S25 -> 0.082139918
C29: Wholesalers' margin | F29: =F25-F31 -> 2317.9424 | G29: =G25-G31 -> 0.5697066 | H29: =H25-H31 -> 2317.9424 | I29: =I25-I31 -> 0.5697066 | J29: =J25-J31 -> 2317.9424 | K29: =K25-K31 -> 0.5697066 | L29: =L25-L31 -> 2317.9424 | M29: =M25-M31 -> 0.5697066 | ... S29: =S25-S31 -> 0.73586881
C30: Wholesalers' Buying Price per carton +VAT | F30: =+F31 -> 30082.058 | G30: =G31 -> 7.3936032 | H30: =+H31 -> 30082.058 | I30: =I31 -> 7.3936032 | J30: =+J31 -> 30082.058 | K30: =K31 -> 7.3936032 | L30: =+L31 -> 30082.058 | M30: =M31 -> 7.3936032 | N30: =+N31 -> 24480 | O30: =O31 -> 6.016723 | P30: =+P31 -> 19380 | Q30: =Q31 -> 4.763239 | R30: =+R31 -> 33456 | S30: =S31 -> 8.2228547
C31: Wholesalers' Buying Price (ctn) | F31: 30082.058 | G31: =+F31/F11 -> 7.3936032 | H31: 30082.058 | I31: =+H31/H11 -> 7.3936032 | J31: 30082.058 | K31: =+J31/J11 -> 7.3936032 | L31: 30082.058 | M31: =+L31/L11 -> 7.3936032 | N31: 24480 | O31: =+N31/N11 -> 6.016723 | P31: 19380 | Q31: =+P31/P11 -> 4.763239 | R31: 33456 | S31: =+R31/R11 -> 8.2228547
B33: Distributor
C34: Distributors' margin (%) | F34: =+F35/F31 -> 0.12480074 | G34: =+G35/G31 -> 0.12480074 | H34: =+H35/H31 -> 0.12681276 | I34: =+I35/I31 -> 0.12681276 | J34: =+J35/J31 -> 0.11909767 | K34: =+K35/K31 -> 0.11909767 | L34: =+L35/L31 -> 0.12480074 | M34: =+M35/M31 -> 0.12480074 | ... S34: =+S35/S31 -> 0.27671104
C35: Distributors' margin | F35: =+F31-F36 -> 3754.2631 | G35: =+G31-G36 -> 0.92272716 | H35: =+H31-H36 -> 3814.7886 | I35: =+I31-I36 -> 0.93760319 | J35: =+J31-J36 -> 3582.7031 | K35: =+K31-K36 -> 0.88056094 | L35: =+L31-L36 -> 3754.2631 | M35: =+M31-M36 -> 0.92272716 | ... S35: =+S31-S36 -> 2.2753547
C36: Distributors' Buying Price | F36: =+G40*F11 -> 26327.794 | G36: =+G40 -> 6.470876 | H36: =+I40*H11 -> 26267.269 | I36: =+I40 -> 6.456 | J36: =+K40*J11 -> 26499.354 | K36: =+K40 -> 6.5130423 | L36: =+M40*L11 -> 26327.794 | M36: =+M40 -> 6.470876 | N36: =+O40*N11 -> 18869.926 | O36: =+O40 -> 4.6378725 | P36: =+Q40*P11 -> 17268.41 | Q36: =+Q40 -> 4.24425 | R36: =+S40*R11 -> 24198.355 | S36: =+S40 -> 5.9475
C37: Additional cost In Land trucking | F37: 0 | H37: 0 | J37: 0 | L37: 0 | N37: 0 | P37: 0 | R37: 0
B38: Importer / Distributor
C39: Landed Cost in pack | E39: USD | F39: =+F40/F9 -> 658.19486 | G39: =+G40/G9 -> 0.1617719 | H39: =+H40/H9 -> 656.68172 | I39: =+I40/I9 -> 0.1614 | J39: =+J40/J9 -> 662.48386 | K39: =+K40/K9 -> 0.16282606 | L39: =+L40/L9 -> 658.19486 | M39: =+M40/M9 -> 0.1617719 | ... S39: =+S40/S9 -> 0.2478125
C40: Landed Cost in carton | E40: USD | F40: =+G40*F11 -> 26327.794 | G40: =+G41+G43+G47+G45 -> 6.470876 | H40: =+I40*H11 -> 26267.269 | I40: =+I41+I43+I47+I45 -> 6.456 | J40: =+K40*J11 -> 26499.354 | K40: =+K41+K43+K47+K45 -> 6.5130423 | L40: =+M40*L11 -> 26327.794 | M40: =+M41+M43+M47+M45 -> 6.470876 | N40: =+O40*N11 -> 18869.926 | O40: =+O41+O43+O47+O45 -> 4.6378725 | P40: =+Q40*P11 -> 17268.41 | Q40: =+Q41+Q43+Q47+Q45 -> 4.24425 | R40: =+S40*R11 -> 24198.355 | S40: =+S41+S43+S47+S45 -> 5.9475
C41: Import duty rate - 5% | E41: USD | G41: =+G42*G47 -> 0.26 | I41: =+I42*I47 -> 0.26 | K41: =+K42*K47 -> 0.26 | M41: =+M42*M47 -> 0.26 | O41: =+O42*O47 -> 0.185 | Q41: =+Q42*Q47 -> 0.1675 | S41: =+S42*S47 -> 0.225
C42: Import duty % | G42: 0.05 | I42: 0.05 | K42: 0.05 | M42: 0.05 | O42: 0.05 | Q42: 0.05 | S42: 0.05
C43: Other charges - Clearance cost | E43: USD | G43: =$D$44/G56 -> 0.46487603 | I43: =$D$44/I56 -> 0.45 | K43: =$D$44/K56 -> 0.50704225 | M43: =$D$44/M56 -> 0.46487603 | O43: =$D$44/O56 -> 0.36437247 | Q43: =$D$44/Q56 -> 0.375 | S43: =$D$44/S56 -> 0.75
C44: Other charges % | D44: 1800 | G44: =G43/G47 -> 0.089399237 | I44: =I43/I47 -> 0.086538462 | K44: =K43/K47 -> 0.097508126 | M44: =M43/M47 -> 0.089399237 | O44: =O43/O47 -> 0.098479046 | Q44: =Q43/Q47 -> 0.1119403 | S44: =S43/S47 -> 0.16666667
C45: VAT in | G45: =(G46*(G47+G41)) -> 0.546 | I45: =(I46*(I47+I41)) -> 0.546 | K45: =(K46*(K47+K41)) -> 0.546 | M45: =(M46*(M47+M41)) -> 0.546 | O45: =(O46*(O47+O41)) -> 0.3885 | Q45: =(Q46*(Q47+Q41)) -> 0.35175 | S45: =(S46*(S47+S41)) -> 0.4725
C46: VAT in (% from CIF + Import duty) | G46: 0.1 | I46: 0.1 | K46: 0.1 | M46: 0.1 | O46: 0.1 | Q46: 0.1 | S46: 0.1
C47: CIF price after support & Freight Surcharge | E47: USD | G47: =G51-G48+G49 -> 5.2 | I47: =I51-I48+I49 -> 5.2 | K47: =K51-K48+K49 -> 5.2 | M47: =M51-M48+M49 -> 5.2 | O47: =O51-O48+O49 -> 3.7 | Q47: =Q51-Q48+Q49 -> 3.35 | S47: =S51-S48+S49 -> 4.5
...

Sheet P&L by Ctn
C1: CIF Incr | D1: =G12/E12-1 -> #REF! | E1: =G12-E12 -> #REF! | I1: CIF Incr | J1: =M12/K12-1 -> #REF! | K1: =M12-K12 -> #REF! | O1: CIF Incr | P1: =T12/Q12-1 -> #REF! | Q1: =T12-Q12 -> #REF!
C2: FOB Incr | D2: =G13/E13-1 -> #REF! | E2: =G13-E13 -> #REF! | I2: FOB Incr | J2: =M13/K13-1 -> #REF! | K2: =M13-K13 -> #REF! | O2: FOB Incr | P2: =T13/Q13-1 -> #REF! | Q2: =T13-Q13 -> #REF!
C3: Net CIF Incr | D3: =G19/E19-1 -> #REF! | E3: =G19-E19 -> #REF! | I3: Net CIF Incr | J3: =M19/K19-1 -> #REF! | K3: =M19-K19 -> #REF! | O3: Net CIF Incr | P3: =T19/Q19-1 -> #REF! | Q3: =T19-Q19 -> #REF!
C4: COGS Incr | D4: =G14/E14-1 -> #REF! | E4: =G14-E14 -> #REF! | I4: COGS Incr | J4: =M14/K14-1 -> #REF! | K4: =M14-K14 -> #REF! | O4: COGS Incr | P4: =T14/Q14-1 -> #REF! | Q4: =T14-Q14 -> #REF!
C5: GP4 (Excl MF) Incr | D5: =G31/E31-1 -> #REF! | E5: =G31-E31 -> #REF! | I5: GP4 (Excl MF) Incr | J5: =M31/K31-1 -> #REF! | K5: =M31-K31 -> #REF! | O5: GP4 (Excl MF) Incr | P5: =T31/Q31-1 -> #REF! | Q5: =T31-Q31 -> #REF!
C8: 1 | D8: 2 | E8: 3 | F8: 4 | G8: 5 | H8: 6 | I8: 7 | J8: 8 | K8: 9 | L8: 10 | M8: 11 | N8: 12 | O8: 13 | P8: 14 | Q8: 15 | R8: 16 | S8: 17 | T8: 18 | U8: 19 | V8: 20 | W8: 21 | X8: 22 | Y8: 23 | Z8: 24 | AA8: 25 | AB8: 26 | AC8: 27 | AD8: 28 | AE8: 29 | AF8: 30 | AG8: 31
F9: Scenario 3 | G9: Scenario +15%, 1100 | H9: Scenario +15%, 1200 | L9: =F9 -> Scenario 3 | M9: =G9 -> Scenario +15%, 1100 | N9: =H9 -> Scenario +15%, 1200 | R9: =L9 -> Scenario 3 | S9: Scenario 4 | T9: =M9 -> Scenario +15%, 1100 | U9: =N9 -> Scenario +15%, 1200 | X9: Freight 1500 | AA9: Freight 1500 | AD9: Freight 1500 | AG9: Freight 1500
C10: GSS LOKAL 40 | D10: GSS LOKAL 40 | E10: GSS LOKAL 40 | F10: GSS LOKAL 40 | G10: GSS LOKAL 40 | H10: GSS LOKAL 40 | I10: IIP LOKAL 40 | J10: IIP LOKAL 40 | K10: IIP LOKAL 40 | L10: IIP LOKAL 40 | M10: IIP LOKAL 40 | N10: IIP LOKAL 40 | O10: IHAG LOKAL 40 | P10: IHAG LOKAL 40 | Q10: IHAG LOKAL 40 | R10: IHAG LOKAL 40 | S10: IHAG LOKAL 40 | T10: IHAG LOKAL 40 | U10: IHAG LOKAL 40 | V10: GPD LOKAL 40 | W10: GPD LOKAL 40 | X10: GPD LOKAL 40 | Y10: PMAD LOKAL 12 | Z10: PMAD LOKAL 12 | AA10: PMAD LOKAL 12 | AB10: CGSS MA (NS) 12 | AC10: CGSS MA (NS) 12 | AD10: CGSS MA (NS) 12 | AE10: PMAJ LOKAL 24 | AF10: PMAJ LOKAL 24 | AG10: PMAJ LOKAL 24
C11: 2020 | D11: 2021 | E11: 2022 | F11: 2022 | G11: 2022 | H11: 2022 | I11: 2020 | J11: 2021 | K11: 2022 | L11: 2022 | M11: 2022 | N11: 2022 | O11: 2020 | P11: 2021 | Q11: 2022 | R11: 2022 | S11: 2022 | T11: 2022 | U11: 2022 | V11: 2021 | W11: 2022 | X11: 2022 | Y11: 2021 | Z11: 2022 | AA11: 2022 | AB11: 2021 | AC11: 2022 | AD11: 2022 | AE11: 2021 | AF11: 2022 | AG11: 2022
A12: 5 | B12: CIF | C12: ='Pricing Structure - All SKU'!G60 -> 5.6 | D12: ='Pricing Structure - All SKU'!I60 -> 5.6 | E12: ='Pricing Structure - All SKU'!K60 -> 6.0429664 | F12: ='Pricing Structure - GSS'!#REF! -> #REF! | G12: ='Pricing Structure - GSS'!#REF! -> #REF! | H12: ='Pricing Structure - GSS'!#REF! -> #REF! | I12: ='Pricing Structure - All SKU'!T60 -> 5.6 | J12: ='Pricing Structure - All SKU'!V60 -> 5.6 | K12: ='Pricing Structure - All SKU'!X60 -> 6.0375316 | L12: ='Pricing Structure - IIP'!#REF! -> #REF! | M12: ='Pricing Structure - IIP'!#REF! -> #REF! | N12: ='Pricing Structure - IIP'!#REF! -> #REF! | O12: ='Pricing Structure - All SKU'!AI60 -> 5.6 | P12: ='Pricing Structure - All SKU'!AK60 -> 5.6 | Q12: ='Pricing Structure - All SKU'!AM60 -> 6.0445945 | R12: ='Pricing Structure - IHAG'!#REF! -> #REF! | S12: ='Pricing Structure - IHAG'!#REF! -> #REF! | T12: ='Pricing Structure - IHAG'!#REF! -> #REF! | U12: ='Pricing Structure - IHAG'!#REF! -> #REF! | V12: ='Pricing Structure - All SKU'!AZ60 -> 5.6 | W12: ='Pricing Structure - All SKU'!BB60 -> 6.0499174 | X12: ='Pricing Structure - All SKU'!BH60 -> 6.0522124 | Y12: ='Pricing Structure - All SKU'!BT60 -> 4.38 | Z12: ='Pricing Structure - All SKU'!BV60 -> 4.38 | AA12: ='Pricing Structure - All SKU'!BZ60 -> 4.5522525 | AB12: ='Pricing Structure - All SKU'!BL60 -> 4.722915 | AC12: ='Pricing Structure - All SKU'!BN60 -> 4.722915 | AD12: ='Pricing Structure - All SKU'!BR60 -> 5.0501487 | AE12: ='Pricing Structure - All SKU'!CB60 -> 6.55 | AF12: ='Pricing Structure - All SKU'!CD60 -> 6.55 | AG12: ='Pricing Structure - All SKU'!CH60 -> 6.5520188
A13: 6 | B13: FOB | C13: ='Pricing Structure - All SKU'!G67 -> 5.439876 | D13: ='Pricing Structure - All SKU'!I67 -> 5.3029959 | E13: ='Pricing Structure - All SKU'!K67 -> 5.7331826 | F13: ='Pricing Structure - GSS'!#REF! -> #REF! | G13: ='Pricing Structure - GSS'!#REF! -> #REF! | H13: ='Pricing Structure - GSS'!#REF! -> #REF! | I13: ='Pricing Structure - All SKU'!T67 -> 5.4375 | J13: ='Pricing Structure - All SKU'!V67 -> 5.3125 | K13: ='Pricing Structure - All SKU'!X67 -> 5.7281473 | L13: ='Pricing Structure - IIP'!#REF! -> #REF! | M13: ='Pricing Structure - IIP'!#REF! -> #REF! | N13: ='Pricing Structure - IIP'!#REF! -> #REF! | O13: ='Pricing Structure - All SKU'!AI67 -> 5.3971831 | P13: ='Pricing Structure - All SKU'!AK67 -> 5.2760563 | Q13: ='Pricing Structure - All SKU'!AM67 -> 5.7048348 | R13: ='Pricing Structure - IHAG'!#REF! -> #REF! | S13: ='Pricing Structure - IHAG'!#REF! -> #REF! | T13: ='Pricing Structure - IHAG'!#REF! -> #REF! | U13: ='Pricing Structure - IHAG'!#REF! -> #REF! | V13: ='Pricing Structure - All SKU'!AZ67 -> 5.3029959 | W13: ='Pricing Structure - All SKU'!BB67 -> 5.74 | X13: ='Pricing Structure - All SKU'!BH67 -> 5.74 | Y13: ='Pricing Structure - All SKU'!BT67 -> 4.13 | Z13: ='Pricing Structure - All SKU'!BV67 -> 4.13 | AA13: ='Pricing Structure - All SKU'!BZ67 -> 4.3 | AB13: ='Pricing Structure - All SKU'!BL67 -> 4.48 | AC13: ='Pricing Structure - All SKU'!BN67 -> 4.48 | AD13: ='Pricing Structure - All SKU'!BR67 -> 4.8 | AE13: ='Pricing Structure - All SKU'!CB67 -> 6.05 | AF13: ='Pricing Structure - All SKU'!CD67 -> 6.05 | AG13: ='Pricing Structure - All SKU'!CH67 -> 6.05
A14: 7 | B14: COGS | C14: ='Pricing Structure - All SKU'!G74 -> 3.2951822 | D14: ='Pricing Structure - All SKU'!I74 -> 3.5328331 | E14: ='Pricing Structure - All SKU'!K74 -> 3.8637981 | F14: ='Pricing Structure - GSS'!#REF! -> #REF! | G14: ='Pricing Structure - GSS'!#REF! -> #REF! | H14: ='Pricing Structure - GSS'!#REF! -> #REF! | I14: ='Pricing Structure - All SKU'!T74 -> 3.7 | J14: ='Pricing Structure - All SKU'!V74 -> 3.9789363 | K14: ='Pricing Structure - All SKU'!X74 -> 4.2894638 | L14: ='Pricing Structure - IIP'!#REF! -> #REF! | M14: ='Pricing Structure - IIP'!#REF! -> #REF! | N14: ='Pricing Structure - IIP'!#REF! -> #REF! | O14: ='Pricing Structure - All SKU'!AI74 -> 4.4243786 | P14: ='Pricing Structure - All SKU'!AK74 -> 4.6419623 | Q14: ='Pricing Structure - All SKU'!AM74 -> 5.0750328 | R14: ='Pricing Structure - IHAG'!#REF! -> #REF! | S14: ='Pricing Structure - IHAG'!#REF! -> #REF! | T14: ='Pricing Structure - IHAG'!#REF! -> #REF! | U14: ='Pricing Structure - IHAG'!#REF! -> #REF! | V14: ='Pricing Structure - All SKU'!AZ74 -> 3.6780718 | W14: ='Pricing Structure - All SKU'!BB74 -> 3.8793987 | X14: ='Pricing Structure - All SKU'!BH74 -> 4.0540541 | Y14: ='Pricing Structure - All SKU'!BT74 -> 2.7993673 | Z14: ='Pricing Structure - All SKU'!BV74 -> 2.8488108 | AA14: ='Pricing Structure - All SKU'!BZ74 -> 3 | AB14: ='Pricing Structure - All SKU'!BL74 -> 2.5589374 | AC14: ='Pricing Structure - All SKU'!BN74 -> 2.6298189 | AD14: ='Pricing Structure - All SKU'!BR74 -> 2.8378378 | AE14: ='Pricing Structure - All SKU'!CB74 -> 4.2400614 | AF14: ='Pricing Structure - All SKU'!CD74 -> 3.9409356 | AG14: ='Pricing Structure - All SKU'!CH74 -> 4.2162162
A15: 8 | B15: GP1 | C15: =C13-C14 -> 2.1446938 | D15: =D13-D14 -> 1.7701627 | E15: =E13-E14 -> 1.8693845 | F15: =F13-F14 -> #REF! | G15: =G13-G14 -> #REF! | H15: =H13-H14 -> #REF! | I15: =I13-I14 -> 1.7375 | J15: =J13-J14 -> 1.3335637 | ... AG15: =AG13-AG14 -> 1.8337838
A16: 9 | B16: GP1% | C16: =C15/C$13 -> 0.39425417 | D16: =D15/D$13 -> 0.33380429 | E16: =E15/E$13 -> 0.32606401 | F16: =F15/F$13 -> #REF! | G16: =G15/G$13 -> #REF! | H16: =H15/H$13 -> #REF! | I16: =I15/I$13 -> 0.31954023 | J16: =J15/J$13 -> 0.25102376 | ... AG16: =AG15/AG$13 -> 0.30310476
A17: 10 | B17: TP | C17: ='Pricing Structure - All SKU'!G57 -> 0.5 | D17: ='Pricing Structure - All SKU'!I57 -> 0.42334055 | E17: ='Pricing Structure - All SKU'!K57 -> 0.79380235 | F17: ='Pricing Structure - GSS'!#REF! -> #REF! | G17: ='Pricing Structure - GSS'!#REF! -> #REF! | H17: ='Pricing Structure - GSS'!#REF! -> #REF! | I17: ='Pricing Structure - All SKU'!T57 -> 0.5 | J17: ='Pricing Structure - All SKU'!V57 -> 0.4 | K17: ='Pricing Structure - All SKU'!X57 -> 0.78897422 | L17: ='Pricing Structure - IIP'!#REF! -> #REF! | M17: ='Pricing Structure - IIP'!#REF! -> #REF! | N17: ='Pricing Structure - IIP'!#REF! -> #REF! | O17: ='Pricing Structure - All SKU'!AI57 -> 0.5 | P17: ='Pricing Structure - All SKU'!AK57 -> 0.41917048 | Q17: ='Pricing Structure - All SKU'!AM57 -> 0.64699696 | R17: ='Pricing Structure - IHAG'!#REF! -> #REF! | S17: ='Pricing Structure - IHAG'!#REF! -> #REF! | T17: ='Pricing Structure - IHAG'!#REF! -> #REF! | U17: ='Pricing Structure - IHAG'!#REF! -> #REF! | V17: ='Pricing Structure - All SKU'!AZ57 -> 0.4 | W17: ='Pricing Structure - All SKU'!BB57 -> 0.8 | X17: ='Pricing Structure - All SKU'!BH57 -> 0.8 | Y17: ='Pricing Structure - All SKU'!BT57 -> 1.03 | Z17: ='Pricing Structure - All SKU'!BV57 -> 1.03 | AA17: ='Pricing Structure - All SKU'!BZ57 -> 0.9 | AB17: ='Pricing Structure - All SKU'!BL57 -> 1.02 | AC17: ='Pricing Structure - All SKU'!BN57 -> 1.02 | AD17: ='Pricing Structure - All SKU'!BR57 -> 1 | AE17: ='Pricing Structure - All SKU'!CB57 -> 1.8 | AF17: ='Pricing Structure - All SKU'!CD57 -> 1.8 | AG17: ='Pricing Structure - All SKU'!CH57 -> 1.45
A18: 11 | B18: TP% | C18: =C17/C$13 -> 0.091913859 | D18: =D17/D13 -> 0.079830451 | E18: =E17/E13 -> 0.13845754 | F18: =F17/F$13 -> #REF! | G18: =G17/G$13 -> #REF! | H18: =H17/H$13 -> #REF! | I18: =I17/I13 -> 0.091954023 | J18: =J17/J13 -> 0.075294118 | K18: =K17/K13 -> 0.13773637 | L18: =L17/L$13 -> #REF! | M18: =M17/M$13 -> #REF! | N18: =N17/N$13 -> #REF! | O18: =O17/O13 -> 0.092640919 | P18: =P17/P13 -> 0.079447689 | Q18: =Q17/Q13 -> 0.11341204 | R18: =R17/R$13 -> #REF! | S18: =S17/S$13 -> #REF! | T18: =T17/T$13 -> #REF! | U18: =U17/U$13 -> #REF! | V18: =V17/V13 -> 0.075429061 | W18: =W17/W13 -> 0.13937282 | X18: =X17/X13 -> 0.13937282 | Y18: =Y17/Y13 -> 0.24939467 | Z18: =Z17/Z13 -> 0.24939467 | AA18: =AA17/AA13 -> 0.20930233 | AB18: =AB17/AB13 -> 0.22767857 | AC18: =AC17/AC13 -> 0.22767857 | ... AG18: =AG17/AG13 -> 0.23966942
A19: 12 | B19: CIF - TP | C19: =C12-C17 -> 5.1 | D19: =D12-D17 -> 5.1766594 | E19: =E12-E17 -> 5.2491641 | F19: =F12-F17 -> #REF! | G19: =G12-G17 -> #REF! | H19: =H12-H17 -> #REF! | I19: =I12-I17 -> 5.1 | J19: =J12-J17 -> 5.2 | ... AG19: =AG12-AG17 -> 5.1020188
A20: 13 | B20: MF | C20: ='Pricing Structure - All SKU'!G92 -> 1.0331208 | D20: ='Pricing Structure - All SKU'!I92 -> 0.82389229 | E20: ='Pricing Structure - All SKU'!K92 -> 0.8851129 | F20: ='Pricing Structure - GSS'!#REF! -> #REF! | G20: ='Pricing Structure - GSS'!#REF! -> #REF! | H20: ='Pricing Structure - GSS'!#REF! -> #REF! | I20: ='Pricing Structure - All SKU'!T92 -> 0.9 | J20: ='Pricing Structure - All SKU'!V92 -> 0.55 | K20: ='Pricing Structure - All SKU'!X92 -> 0.39456602 | L20: ='Pricing Structure - IIP'!#REF! -> #REF! | M20: ='Pricing Structure - IIP'!#REF! -> #REF! | N20: ='Pricing Structure - IIP'!#REF! -> #REF! | O20: ='Pricing Structure - All SKU'!AI92 -> 0 | P20: ='Pricing Structure - All SKU'!AK92 -> 0 | Q20: ='Pricing Structure - All SKU'!AM92 -> 0 | R20: ='Pricing Structure - IHAG'!#REF! -> #REF! | S20: ='Pricing Structure - IHAG'!#REF! -> #REF! | T20: ='Pricing Structure - IHAG'!#REF! -> #REF! | U20: ='Pricing Structure - IHAG'!#REF! -> #REF! | V20: 0 | W20: 0 | X20: 0 | Y20: 0 | Z20: 0 | AA20: 0 | AB20: 0 | AC20: 0 | AD20: 0 | AE20: 0 | AF20: 0 | AG20: 0
A21: 14 | B21: MF% | C21: =C20/C$13 -> 0.18991623 | D21: =D20/D15 -> 0.46543307 | E21: =E20/E15 -> 0.47347825 | F21: =F20/F$13 -> #REF! | G21: =G20/G$13 -> #REF! | H21: =H20/H$13 -> #REF! | I21: =I20/I15 -> 0.51798561 | J21: =J20/J15 -> 0.41242873 | K21: =K20/K15 -> 0.27425492 | L21: =L20/L$13 -> #REF! | M21: =M20/M$13 -> #REF! | N21: =N20/N$13 -> #REF! | O21: =O20/O15 -> 0 | P21: =P20/P15 -> 0 | Q21: =Q20/Q15 -> 0 | R21: =R20/R$13 -> #REF! | S21: =S20/S$13 -> #REF! | T21: =T20/T$13 -> #REF! | U21: =U20/U$13 -> #REF! | V21: =V20/V15 -> 0 | W21: =W20/W15 -> 0 | X21: =X20/X15 -> 0 | Y21: =Y20/Y15 -> 0 | Z21: =Z20/Z15 -> 0 | AA21: =AA20/AA15 -> 0 | AB21: =AB20/AB15 -> 0 | AC21: =AC20/AC15 -> 0 | ... AG21: =AG20/AG15 -> 0
A22: 15 | B22: VSE | C22: ='Pricing Structure - All SKU'!G72 -> 0.11589149 | D22: ='Pricing Structure - All SKU'!I72 -> 0.11746357 | E22: ='Pricing Structure - All SKU'!K72 -> 0.13716874 | F22: ='Pricing Structure - GSS'!#REF! -> #REF! | G22: ='Pricing Structure - GSS'!#REF! -> #REF! | H22: ='Pricing Structure - GSS'!#REF! -> #REF! | I22: ='Pricing Structure - All SKU'!T72 -> 0.11234678 | J22: ='Pricing Structure - All SKU'!V72 -> 0.11387219 | K22: ='Pricing Structure - All SKU'!X72 -> 0.10059002 | L22: ='Pricing Structure - IIP'!#REF! -> #REF! | M22: ='Pricing Structure - IIP'!#REF! -> #REF! | N22: ='Pricing Structure - IIP'!#REF! -> #REF! | O22: ='Pricing Structure - All SKU'!AI72 -> 0.12593901 | P22: ='Pricing Structure - All SKU'!AK72 -> 0.12764335 | Q22: ='Pricing Structure - All SKU'!AM72 -> 0.10951514 | R22: ='Pricing Structure - IHAG'!#REF! -> #REF! | S22: ='Pricing Structure - IHAG'!#REF! -> #REF! | T22: ='Pricing Structure - IHAG'!#REF! -> #REF! | U22: ='Pricing Structure - IHAG'!#REF! -> #REF! | V22: ='Pricing Structure - All SKU'!AZ72 -> 0.11589149 | W22: ='Pricing Structure - All SKU'!BB72 -> 0.11762592 | X22: ='Pricing Structure - All SKU'!BH72 -> 0.11517897 | Y22: ='Pricing Structure - All SKU'!BT72 -> 0.041738561 | Z22: ='Pricing Structure - All SKU'!BV72 -> 0.038391337 | AA22: ='Pricing Structure - All SKU'!BZ72 -> 0.038391337 | AB22: ='Pricing Structure - All SKU'!BL72 -> 0.040963349 | AC22: ='Pricing Structure - All SKU'!BN72 -> 0.036717558 | AD22: ='Pricing Structure - All SKU'!BR72 -> 0.036717558 | AE22: ='Pricing Structure - All SKU'!CB72 -> 0.082051204 | AF22: ='Pricing Structure - All SKU'!CD72 -> 0.082651304 | AG22: ='Pricing Structure - All SKU'!CH72 -> 0.082651304
A23: 16 | B23: GP2 | C23: =C15-C17-C20-C22 -> 0.49568157 | D23: =D15-D17-D20-D22 -> 0.40546634 | E23: =E15-E17-E20-E22 -> 0.053300503 | F23: =F15-F17-F20-F22 -> #REF! | G23: =G15-G17-G20-G22 -> #REF! | H23: =H15-H17-H20-H22 -> #REF! | I23: =I15-I17-I20-I22 -> 0.22515322 | J23: =J15-J17-J20-J22 -> 0.26969155 | ... AG23: =AG15-AG17-AG20-AG22 -> 0.30113248
A24: 17 | B24: GP2% | C24: =C23/C$13 -> 0.091120012 | D24: =D23/D$13 -> 0.076459864 | E24: =E23/E$13 -> 0.0092968438 | F24: =F23/F$13 -> #REF! | G24: =G23/G$13 -> #REF! | H24: =H23/H$13 -> #REF! | I24: =I23/I$13 -> 0.041407489 | J24: =J23/J$13 -> 0.050765469 | ... AG24: =AG23/AG$13 -> 0.049773964
A25: 18 | B25: A&P | C25: ='Pricing Structure - All SKU'!G78 -> 0 | D25: ='Pricing Structure - All SKU'!I78 -> 0 | E25: ='Pricing Structure - All SKU'!K78 -> 0 | F25: 0 | G25: 0 | H25: 0 | I25: ='Pricing Structure - All SKU'!T78 -> 0 | J25: ='Pricing Structure - All SKU'!V78 -> 0 | K25: ='Pricing Structure - All SKU'!X78 -> 0 | L25: 0 | M25: 0 | N25: 0 | O25: ='Pricing Structure - All SKU'!AI78 -> 0 | P25: ='Pricing Structure - All SKU'!AK78 -> 0 | Q25: ='Pricing Structure - All SKU'!AM78 -> 0 | R25: 0 | S25: 0 | T25: 0 | U25: 0 | V25: 0 | W25: 0 | X25: 0 | Y25: 0 | Z25: 0 | AA25: 0 | AB25: 0 | AC25: 0 | AD25: 0 | AE25: 0 | AF25: 0 | AG25: 0
A26: 19 | B26: GP3 | C26: =C23-C25 -> 0.49568157 | D26: =D23-D25 -> 0.40546634 | E26: =E23-E25 -> 0.053300503 | F26: =F23-F25 -> #REF! | G26: =G23-G25 -> #REF! | H26: =H23-H25 -> #REF! | I26: =I23-I25 -> 0.22515322 | J26: =J23-J25 -> 0.26969155 | ... AG26: =AG23-AG25 -> 0.30113248
A27: 20 | B27: GP3% | C27: =C26/C$13 -> 0.091120012 | D27: =D26/D$13 -> 0.076459864 | E27: =E26/E$13 -> 0.0092968438 | F27: =F26/F$13 -> #REF! | G27: =G26/G$13 -> #REF! | H27: =H26/H$13 -> #REF! | I27: =I26/I$13 -> 0.041407489 | J27: =J26/J$13 -> 0.050765469 | ... AG27: =AG26/AG$13 -> 0.049773964
A28: 21 | B28: Freight Difference | C28: ='Pricing Structure - All SKU'!G96 -> 0.14979339 | D28: ='Pricing Structure - All SKU'!I96 -> 0.012913223 | E28: ='Pricing Structure - All SKU'!K96 -> -0.0045096113 | F28: ='Pricing Structure - GSS'!#REF! -> #REF! | G28: ='Pricing Structure - GSS'!#REF! -> #REF! | H28: ='Pricing Structure - GSS'!#REF! -> #REF! | I28: ='Pricing Structure - All SKU'!T96 -> 0.13737078 | J28: ='Pricing Structure - All SKU'!V96 -> 0.012370779 | K28: ='Pricing Structure - All SKU'!X96 -> 0.027076247 | L28: ='Pricing Structure - IIP'!#REF! -> #REF! | M28: ='Pricing Structure - IIP'!#REF! -> #REF! | N28: ='Pricing Structure - IIP'!#REF! -> #REF! | O28: ='Pricing Structure - All SKU'!AI96 -> 0.16416203 | P28: ='Pricing Structure - All SKU'!AK96 -> 0.043035268 | Q28: ='Pricing Structure - All SKU'!AM96 -> -0.0089872836 | R28: ='Pricing Structure - IHAG'!#REF! -> #REF! | S28: ='Pricing Structure - IHAG'!#REF! -> #REF! | T28: ='Pricing Structure - IHAG'!#REF! -> #REF! | U28: ='Pricing Structure - IHAG'!#REF! -> #REF! | V28: ='Pricing Structure - All SKU'!AZ96 -> 0.0062609198 | W28: ='Pricing Structure - All SKU'!BB96 -> -0.0066523034 | X28: ='Pricing Structure - All SKU'!BH96 -> -0.077479339 | Y28: ='Pricing Structure - All SKU'!BT96 -> 0.040847469 | Z28: ='Pricing Structure - All SKU'!BV96 -> 0.008214092 | AA28: ='Pricing Structure - All SKU'!BZ96 -> -0.0625 | AB28: ='Pricing Structure - All SKU'!BL96 -> 0.022792124 | AC28: ='Pricing Structure - All SKU'!BN96 -> 0.026609261 | AD28: ='Pricing Structure - All SKU'!BR96 -> -0.060728745 | AE28: ='Pricing Structure - All SKU'!CB96 -> -0.16745423 | AF28: ='Pricing Structure - All SKU'!CD96 -> -0.23874774 | AG28: ='Pricing Structure - All SKU'!CH96 -> -0.125
A29: 22 | B29: GP4 | C29: =C26-C28 -> 0.34588818 | D29: =D26-D28 -> 0.39255312 | E29: =E26-E28 -> 0.057810114 | F29: =F26-F28 -> #REF! | G29: =G26-G28 -> #REF! | H29: =H26-H28 -> #REF! | I29: =I26-I28 -> 0.087782445 | J29: =J26-J28 -> 0.25732077 | ... AG29: =AG26-AG28 -> 0.42613248
A30: 23 | B30: GP4% | C30: =C29/C$13 -> 0.063583836 | D30: =D29/D$13 -> 0.074024783 | E30: =E29/E$13 -> 0.010083425 | F30: =F29/F$13 -> #REF! | G30: =G29/G$13 -> #REF! | H30: =H29/H$13 -> #REF! | I30: =I29/I$13 -> 0.016143898 | J30: =J29/J$13 -> 0.048436852 | ... AG30: =AG29/AG$13 -> 0.070435121
A31: 24 | B31: GP4 (Exclude MF) | C31: =C29+C20 -> 1.379009 | D31: =D29+D20 -> 1.2164454 | E31: =E29+E20 -> 0.94292302 | F31: =F29+F20 -> #REF! | G31: =G29+G20 -> #REF! | H31: =H29+H20 -> #REF! | I31: =I29+I20 -> 0.98778244 | J31: =J29+J20 -> 0.80732077 | ... AG31: =AG29+AG20 -> 0.42613248
A32: 25
A33: 26 | B33: Distributor Buying Value | C33: ='Pricing Structure - All SKU'!G45 -> 6.355376 | D33: ='Pricing Structure - All SKU'!I45 -> 6.4439177 | E33: ='Pricing Structure - GSS'!O45 -> 6.5251783 | F33: =F47 -> #REF! | G33: =G47 -> #REF! | H33: =H47 -> #REF! | I33: ='Pricing Structure - IIP'!G45 -> 6.3405 | J33: ='Pricing Structure - IIP'!I45 -> 6.456 | K33: ='Pricing Structure - IIP'!O45 -> 6.5214073 | L33: =L47 -> #REF! | M33: =M47 -> #REF! | N33: =N47 -> #REF! | O33: ='Pricing Structure - IHAG'!G45 -> 6.3975423 | P33: ='Pricing Structure - IHAG'!I45 -> 6.5130423 | Q33: ='Pricing Structure - IHAG'!O45 -> 6.7293686 | R33: =R47 -> #REF! | S33: =S47 -> #REF! | T33: =T47 -> #REF! | U33: =U47 -> #REF! | V33: ='Pricing Structure - All SKU'!AZ45 -> 6.470876 | W33: ='Pricing Structure - All SKU'!BB45 -> 6.5285306 | X33: ='Pricing Structure - All SKU'!BH45 -> 6.5311813 | Y33: ='Pricing Structure - All SKU'!BT45 -> 4.24425 | Z33: ='Pricing Structure - All SKU'!BV45 -> 4.24425 | AA33: ='Pricing Structure - All SKU'!BZ45 -> 4.5933516 | AB33: ='Pricing Structure - All SKU'!BL45 -> 4.6412393 | AC33: ='Pricing Structure - All SKU'!BN45 -> 4.6412393 | AD33: ='Pricing Structure - All SKU'!BR45 -> 5.0422943 | AE33: ='Pricing Structure - All SKU'!CB45 -> 6.23625 | AF33: ='Pricing Structure - All SKU'!CD45 -> 6.23625 | AG33: ='Pricing Structure - All SKU'!CH45 -> 6.6428317
A34: 27 | B34: Distributor Selling Value | C34: ='Pricing Structure - All SKU'!G32 -> 7.36 | D34: ='Pricing Structure - All SKU'!I32 -> 7.36 | E34: ='Pricing Structure - GSS'!O32 -> 7.3377472 | F34: =F48 -> #REF! | G34: =G48 -> #REF! | H34: =H48 -> #REF! | I34: ='Pricing Structure - IIP'!G32 -> 7.36 | J34: ='Pricing Structure - IIP'!I32 -> 7.36 | K34: ='Pricing Structure - IIP'!O32 -> 7.3377472 | L34: =L48 -> #REF! | M34: =M48 -> #REF! | N34: =N48 -> #REF! | O34: ='Pricing Structure - IHAG'!G32 -> 7.36 | P34: ='Pricing Structure - IHAG'!I32 -> 7.36 | Q34: ='Pricing Structure - IHAG'!O32 -> 7.3946099 | R34: =R48 -> #REF! | S34: =S48 -> #REF! | T34: =T48 -> #REF! | U34: =U48 -> #REF! | V34: ='Pricing Structure - All SKU'!AZ32 -> 7.36 | W34: ='Pricing Structure - All SKU'!BB32 -> 7.3394363 | X34: ='Pricing Structure - All SKU'!BH32 -> 7.3377472 | Y34: ='Pricing Structure - All SKU'!BT32 -> 4.3181818 | Z34: ='Pricing Structure - All SKU'!BV32 -> 4.3181818 | AA34: ='Pricing Structure - All SKU'!BZ32 -> 4.7272727 | AB34: ='Pricing Structure - All SKU'!BL32 -> 6.016723 | AC34: ='Pricing Structure - All SKU'!BN32 -> 6 | AD34: ='Pricing Structure - All SKU'!BR32 -> 6.1 | AE34: ='Pricing Structure - All SKU'!CB32 -> 8.2228547 | AF34: ='Pricing Structure - All SKU'!CD32 -> 7.2888889 | AG34: ='Pricing Structure - All SKU'!CH32 -> 7.9111111
A35: 28 | B35: Distributor Margin | C35: =C34-C$33-'Pricing Structure - All SKU'!G41 -> 0.87103306 | D35: =D34-D$33-'Pricing Structure - All SKU'!I41 -> 0.79054064 | E35: =E34-E$33-'Pricing Structure - GSS'!O41 -> 0.69643753 | F35: =F49 -> #REF! | G35: =G49 -> #REF! | H35: =H49 -> #REF! | I35: =I34-I$33-'Pricing Structure - IIP'!G41 -> 0.88590909 | J35: =J34-J$33-'Pricing Structure - IIP'!I41 -> 0.78090909 | K35: =K34-K$33-'Pricing Structure - IIP'!O41 -> 0.6998657 | L35: =L49 -> #REF! | M35: =M49 -> #REF! | N35: =N49 -> #REF! | O35: =O34-O$33-'Pricing Structure - IHAG'!G41 -> 0.82886684 | P35: =P34-P$33-'Pricing Structure - IHAG'!I41 -> 0.72386684 | Q35: =Q34-Q$33-'Pricing Structure - IHAG'!O41 -> 0.55866999 | R35: =R49 -> #REF! | S35: =S49 -> #REF! | T35: =T49 -> #REF! | U35: =U49 -> #REF! | V35: =V34-V$33-'Pricing Structure - All SKU'!AZ41 -> 0.76603306 | W35: =W34-W$33-'Pricing Structure - All SKU'!BB41 -> 0.69492561 | X35: =X34-X$33-'Pricing Structure - All SKU'!BH41 -> 0.69098023 | Y35: =Y34-Y$33-'Pricing Structure - All SKU'!BT41 -> 0.033119835 | Z35: =Z34-Z$33-'Pricing Structure - All SKU'!BV41 -> 0.033119835 | AA35: =AA34-AA$33-'Pricing Structure - All SKU'!BZ41 -> 0.087655536 | AB35: =AB34-AB$33-'Pricing Structure - All SKU'!BL41 -> 1.2173149 | AC35: =AC34-AC$33-'Pricing Structure - All SKU'!BN41 -> 1.2021123 | AD35: =AD34-AD$33-'Pricing Structure - All SKU'!BR41 -> 0.92842589 | AE35: =AE34-AE$33-'Pricing Structure - All SKU'!CB41 -> 1.7378225 | AF35: =AF34-AF$33-'Pricing Structure - All SKU'!CD41 -> 0.88876263 | AG35: =AG34-AG$33-'Pricing Structure - All SKU'!CH41 -> 1.0847995
A36: 29 | B36: Distributor Margin % | C36: =IFERROR(C35/C34,0) -> 0.11834688 | D36: =IFERROR(D35/D34,0) -> 0.10741041 | E36: =IFERROR(E35/E34,0) -> 0.094911629 | F36: =F50 -> 0 | G36: =IFERROR(G35/G34,0) -> 0 | H36: =IFERROR(H35/H34,0) -> 0 | I36: =IFERROR(I35/I34,0) -> 0.12036808 | J36: =IFERROR(J35/J34,0) -> 0.10610178 | K36: =IFERROR(K35/K34,0) -> 0.095378825 | L36: =IFERROR(L35/L34,0) -> 0 | M36: =IFERROR(M35/M34,0) -> 0 | N36: =IFERROR(N35/N34,0) -> 0 | ... AG36: =IFERROR(AG35/AG34,0) -> 0.13712353
A37: 30 | B37: Growth | D37: =D35/C35-1 -> -0.092410296 | E37: =E35/D35-1 -> -0.11903639 | F37: =F35/E35-1 -> #REF! | G37: =G35/E35-1 -> #REF! | H37: =H35/E35-1 -> #REF! | J37: =J35/I35-1 -> -0.11852232 | K37: =K35/J35-1 -> -0.10378082 | L37: =L35/K35-1 -> #REF! | M37: =M35/K35-1 -> #REF! | N37: =N35/K35-1 -> #REF! | P37: =P35/O35-1 -> -0.12667897 | Q37: =Q35/P35-1 -> -0.22821442 | R37: =R35/Q35-1 -> #REF! | S37: =S35/Q35-1 -> #REF! | T37: =T35/Q35-1 -> #REF! | U37: =U35/Q35-1 -> #REF! | W37: =W35/S35-1 -> #REF! | X37: =X35/V35-1 -> -0.097975963 | Z37: =Z35/X35-1 -> -0.95206833 | AA37: =AA35/Y35-1 -> 1.6466176 | AC37: =AC35/AA35-1 -> 12.714048 | AD37: =AD35/AB35-1 -> -0.23731661 | AF37: =AF35/AD35-1 -> -0.042720978 | AG37: =AG35/AE35-1 -> -0.37577081
A38: 31
A39: 32 | B39: CBP | E39: 1000 | F39: 1000 | G39: 1100 | H39: 1200 | K39: 1000 | L39: 1000 | M39: 1100 | N39: 1200 | Q39: 1000 | S39: 1200 | T39: 1100 | U39: 1200
C41: =IF(C31>C35,"IOD > Dist","IOD < Dist") -> IOD > Dist | D41: =IF(D31>D35,"IOD > Dist","IOD < Dist") -> IOD > Dist | E41: =IF(E31>E35,"IOD > Dist","IOD < Dist") -> IOD > Dist | F41: =IF(F31>G35,"IOD > Dist","IOD < Dist") -> #REF! | G41: =IF(H31>H35,"IOD > Dist","IOD < Dist") -> #REF! | H41: =IF(I31>I35,"IOD > Dist","IOD < Dist") -> IOD > Dist | I41: =IF(J31>J35,"IOD > Dist","IOD < Dist") -> IOD > Dist | J41: =IF(K31>K35,"IOD > Dist","IOD < Dist") -> IOD < Dist | K41: =IF(L31>L35,"IOD > Dist","IOD < Dist") -> #REF! | L41: =IF(N31>N35,"IOD > Dist","IOD < Dist") -> #REF! | M41: =IF(O31>O35,"IOD > Dist","IOD < Dist") -> IOD < Dist | N41: =IF(P31>P35,"IOD > Dist","IOD < Dist") -> IOD < Dist | O41: =IF(Q31>Q35,"IOD > Dist","IOD < Dist") -> IOD < Dist | P41: =IF(R31>R35,"IOD > Dist","IOD < Dist") -> #REF! | Q41: =IF(S31>S35,"IOD > Dist","IOD < Dist") -> #REF! | R41: =IF(U31>U35,"IOD > Dist","IOD < Dist") -> #REF! | S41: =IF(V31>V35,"IOD > Dist","IOD < Dist") -> IOD > Dist | T41: =IF(W31>W35,"IOD > Dist","IOD < Dist") -> IOD > Dist | U41: =IF(X31>X35,"IOD > Dist","IOD < Dist") -> IOD > Dist | V41: =IF(Y31>Y35,"IOD > Dist","IOD < Dist") -> IOD > Dist | W41: =IF(Z31>Z35,"IOD > Dist","IOD < Dist") -> IOD > Dist | X41: =IF(AA31>AA35,"IOD > Dist","IOD < Dist") -> IOD > Dist | Y41: =IF(AB31>AB35,"IOD > Dist","IOD < Dist") -> IOD < Dist | ... AD41: =IF(AG31>AG35,"IOD > Dist","IOD < Dist") -> IOD < Dist
D46: Scenario 1 | E46: Scenario 2 | F46: Scenario 3 | G46: =G9 -> Scenario +15%, 1100 | H46: =H9 -> Scenario +15%, 1200 | J46: Scenario 1 | K46: Scenario 2 | L46: Scenario 3 | M46: =G46 -> Scenario +15%, 1100 | N46: =H46 -> Scenario +15%, 1200 | P46: Scenario 1 | Q46: Scenario 2 | R46: Scenario 3 | S46: Scenario 4 | T46: =M46 -> Scenario +15%, 1100 | U46: =N46 -> Scenario +15%, 1200
B47: Distributor Buying Value | D47: ='Pricing Structure - GSS'!#REF! -> #REF! | E47: ='Pricing Structure - GSS'!#REF! -> #REF! | F47: ='Pricing Structure - GSS'!#REF! -> #REF! | G47: ='Pricing Structure - GSS'!#REF! -> #REF! | H47: ='Pricing Structure - GSS'!#REF! -> #REF! | J47: ='Pricing Structure - IIP'!#REF! -> #REF! | K47: ='Pricing Structure - IIP'!#REF! -> #REF! | L47: ='Pricing Structure - IIP'!#REF! -> #REF! | M47: ='Pricing Structure - IIP'!#REF! -> #REF! | N47: ='Pricing Structure - IIP'!#REF! -> #REF! | P47: ='Pricing Structure - IHAG'!#REF! -> #REF! | Q47: ='Pricing Structure - IHAG'!#REF! -> #REF! | R47: ='Pricing Structure - IHAG'!#REF! -> #REF! | S47: ='Pricing Structure - IHAG'!#REF! -> #REF! | T47: ='Pricing Structure - IHAG'!#REF! -> #REF! | U47: ='Pricing Structure - IHAG'!#REF! -> #REF!
...

Sheet P&L TOTAL 150
B2: Scenario 1000 | C2: 3 | D2: 9 | E2: 15 | F2: 21 | G2: 27 | H2: 24 | I2: 30
B3: Scenario 1100 | C3: 5 | D3: 11 | E3: 19 | F3: 22 | G3: 28 | H3: 25 | I3: 31
B5: Scenario COGS 1 | C5: 3 | D5: 9 | E5: 15 | F5: 21 | G5: 27 | H5: 24 | I5: 30
B6: Scenario COGS 2 | C6: 5 | D6: 11 | E6: 19 | F6: 22 | G6: 28 | H6: 25 | I6: 31
B7: Scenario COGS 3 | C7: 5 | D7: 11 | E7: 19 | F7: 22 | G7: 28 | H7: 25 | I7: 31
B9: Scenario | C9: 1 | K9: 1 | S9: 1 | AA9: 1 | AI9: 1 | AQ9: 1 | AY9: 2 | BG9: 2 | BO9: 2 | BW9: 2 | CE9: 2 | CM9: 2
C10: =IF($C9=1,$C2,$C3) -> 3 | D10: =IF($C9=1,$D2,$D3) -> 9 | E10: =IF($C9=1,$E2,$E3) -> 15 | F10: =IF($C9=1,$F2,$F3) -> 21 | G10: =IF($C9=1,$G2,$G3) -> 27 | H10: =IF($C9=1,$H2,$H3) -> 24 | I10: =IF($I9=1,$I2,$I3) -> 31 | K10: =IF(K9=1,$C2,$C3) -> 3 | L10: =IF(K9=1,$D2,$D3) -> 9 | M10: =IF(K9=1,$E2,$E3) -> 15 | N10: =IF(K9=1,$F2,$F3) -> 21 | O10: =IF(K9=1,$G2,$G3) -> 27 | P10: =IF(K9=1,$H2,$H3) -> 24 | Q10: =IF(K9=1,$I2,$I3) -> 30 | S10: =IF(S9=1,$C2,$C3) -> 3 | T10: =IF(S9=1,$D2,$D3) -> 9 | U10: =IF(S9=1,$E2,$E3) -> 15 | V10: =IF(S9=1,$F2,$F3) -> 21 | W10: =IF(S9=1,$G2,$G3) -> 27 | X10: =IF(S9=1,$H2,$H3) -> 24 | Y10: =IF(S9=1,$I2,$I3) -> 30 | AA10: =IF(AA9=1,$C2,$C3) -> 3 | AB10: =IF(AA9=1,$D2,$D3) -> 9 | AC10: =IF(AA9=1,$E2,$E3) -> 15 | AD10: =IF(AA9=1,$F2,$F3) -> 21 | AE10: =IF(AA9=1,$G2,$G3) -> 27 | AF10: =IF(AA9=1,$H2,$H3) -> 24 | AG10: =IF(AA9=1,$I2,$I3) -> 30 | AI10: =IF(AI9=1,$C2,$C3) -> 3 | AJ10: =IF(AI9=1,$D2,$D3) -> 9 | AK10: =IF(AI9=1,$E2,$E3) -> 15 | AL10: =IF(AI9=1,$F2,$F3) -> 21 | AM10: =IF(AI9=1,$G2,$G3) -> 27 | AN10: =IF(AI9=1,$H2,$H3) -> 24 | AO10: =IF(AI9=1,$I2,$I3) -> 30 | AQ10: =IF(AQ9=1,$C2,$C3) -> 3 | AR10: =IF(AQ9=1,$D2,$D3) -> 9 | AS10: =IF(AQ9=1,$E2,$E3) -> 15 | AT10: =IF(AQ9=1,$F2,$F3) -> 21 | AU10: =IF(AQ9=1,$G2,$G3) -> 27 | AV10: =IF(AQ9=1,$H2,$H3) -> 24 | AW10: =IF(AQ9=1,$I2,$I3) -> 30 | AY10: =IF(AY9=1,$C2,$C3) -> 5 | AZ10: =IF(AY9=1,$D2,$D3) -> 11 | BA10: =IF(AY9=1,$E2,$E3) -> 19 | BB10: =IF(AY9=1,$F2,$F3) -> 22 | BC10: =IF(AY9=1,$G2,$G3) -> 28 | BD10: =IF(AY9=1,$H2,$H3) -> 25 | BE10: =IF(AY9=1,$I2,$I3) -> 31 | BG10: =IF(BG9=1,$C2,$C3) -> 5 | BH10: =IF(BG9=1,$D2,$D3) -> 11 | BI10: =IF(BG9=1,$E2,$E3) -> 19 | BJ10: =IF(BG9=1,$F2,$F3) -> 22 | BK10: =IF(BG9=1,$G2,$G3) -> 28 | BL10: =IF(BG9=1,$H2,$H3) -> 25 | BM10: =IF(BG9=1,$I2,$I3) -> 31 | BO10: =IF(BO9=1,$C2,$C3) -> 5 | BP10: =IF(BO9=1,$D2,$D3) -> 11 | BQ10: =IF(BO9=1,$E2,$E3) -> 19 | BR10: =IF(BO9=1,$F2,$F3) -> 22 | BS10: =IF(BO9=1,$G2,$G3) -> 28 | BT10: =IF(BO9=1,$H2,$H3) -> 25 | BU10: =IF(BO9=1,$I2,$I3) -> 31 | BW10: =IF(BW9=1,$C2,$C3) -> 5 | BX10: =IF(BW9=1,$D2,$D3) -> 11 | BY10: =IF(BW9=1,$E2,$E3) -> 19 | BZ10: =IF(BW9=1,$F2,$F3) -> 22 | CA10: =IF(BW9=1,$G2,$G3) -> 28 | CB10: =IF(BW9=1,$H2,$H3) -> 25 | CC10: =IF(BW9=1,$I2,$I3) -> 31 | CE10: =IF(CE9=1,$C2,$C3) -> 5 | CF10: =IF(CE9=1,$D2,$D3) -> 11 | CG10: =IF(CE9=1,$E2,$E3) -> 19 | CH10: =IF(CE9=1,$F2,$F3) -> 22 | CI10: =IF(CE9=1,$G2,$G3) -> 28 | CJ10: =IF(CE9=1,$H2,$H3) -> 25 | CK10: =IF(CE9=1,$I2,$I3) -> 31 | CM10: =IF(CM9=1,$C2,$C3) -> 5 | CN10: =IF(CM9=1,$D2,$D3) -> 11 | CO10: =IF(CM9=1,$E2,$E3) -> 19 | CP10: =IF(CM9=1,$F2,$F3) -> 22 | CQ10: =IF(CM9=1,$G2,$G3) -> 28 | CR10: =IF(CM9=1,$H2,$H3) -> 25 | CS10: =IF(CM9=1,$I2,$I3) -> 31
B11: Scenario COGS | J11: Actual Jan | R11: Actual Feb | Z11: Actual Feb | AA11: =AH11 -> Q2 | AH11: Q2 | AI11: =AP11 -> Q2 | AP11: Q2 | AQ11: =AX11 -> Q2 | AX11: Q2 | AY11: =BF11 -> Q4 | BF11: Q4 | BG11: =BN11 -> Q4 | BN11: Q4 | BO11: =BV11 -> Q4 | BV11: Q4 | BW11: =CD11 -> Q4 | CD11: Q4 | CE11: =CL11 -> Q4 | CL11: Q4 | CM11: =CT11 -> Q4 | CT11: Q4
J12: =J24/J16 -> 0.62652933 | R12: =R24/R16 -> 0.39722463 | Z12: =Z24/Z16 -> 0.38935033 | AA12: =AA24/AA16 -> 0.8851129 | AB12: =AB24/AB16 -> 0.39456602 | AC12: =AC24/AC16 -> 0 | AD12: =AD24/AD16 -> #DIV/0! | AE12: =AE24/AE16 -> 0 | AF12: =AF24/AF16 -> 0 | AG12: =AG24/AG16 -> 0 | AH12: =AH24/AH16 -> 0.43563356 | AI12: 0.6 | AJ12: 0.15 | AK12: 0 | AL12: 0 | AM12: 0 | AN12: 0 | AO12: 0 | AP12: =AP24/AP16 -> 0.28355357 | AQ12: 0.6 | AR12: 0.15 | AS12: 0 | AT12: 0 | AU12: 0 | AV12: 0 | AW12: 0 | AX12: =AX24/AX16 -> 0.27917974 | AY12: =AY24/AY16 -> #REF! | AZ12: =AZ24/AZ16 -> #REF! | BA12: =BA24/BA16 -> #REF! | BB12: =BB24/BB16 -> #DIV/0! | BC12: =BC24/BC16 -> #DIV/0! | BD12: =BD24/BD16 -> 0 | BE12: =BE24/BE16 -> #DIV/0! | BF12: =BF24/BF16 -> #REF! | BN12: =BN24/BN16 -> #REF! | BV12: =BV24/BV16 -> #REF! | CD12: =CD24/CD16 -> #REF! | CL12: =CL24/CL16 -> #REF! | CT12: =CT24/CT16 -> #REF!
C13: Jan | K13: Feb | S13: Mar | AA13: Apr | AI13: May | AQ13: Jun | AY13: Jul | BG13: Aug | BO13: Sep | BW13: Oct | CE13: Nov | CM13: Dec | CU13: TOTAL
B14: Jan-Mar | C14: GSS LOKAL 40 | D14: IIP LOKAL 40 | E14: IHAG LOKAL 40 | F14: GPD LOKAL 40 | G14: CGSS MA (NS) 12 | H14: PMAD LOKAL 12 | I14: PMAJ LOKAL 24 | J14: JAN | K14: GSS LOKAL 40 | L14: IIP LOKAL 40 | M14: IHAG LOKAL 40 | N14: GPD LOKAL 40 | O14: CGSS MA (NS) 12 | P14: PMAD LOKAL 12 | Q14: PMAJ LOKAL 24 | R14: FEB | S14: GSS LOKAL 40 | T14: IIP LOKAL 40 | U14: IHAG LOKAL 40 | V14: GPD LOKAL 40 | W14: CGSS MA (NS) 12 | X14: PMAD LOKAL 12 | Y14: PMAJ LOKAL 24 | Z14: MAR | AA14: GSS LOKAL 40 | AB14: IIP LOKAL 40 | AC14: IHAG LOKAL 40 | AD14: GPD LOKAL 40 | AE14: CGSS MA (NS) 12 | AF14: PMAD LOKAL 12 | AG14: PMAJ LOKAL 24 | AH14: APR | AI14: GSS LOKAL 40 | AJ14: IIP LOKAL 40 | AK14: IHAG LOKAL 40 | AL14: GPD LOKAL 40 | AM14: CGSS MA (NS) 12 | AN14: PMAD LOKAL 12 | AO14: PMAJ LOKAL 24 | AP14: MAY | AQ14: GSS LOKAL 40 | AR14: IIP LOKAL 40 | AS14: IHAG LOKAL 40 | AT14: GPD LOKAL 40 | AU14: CGSS MA (NS) 12 | AV14: PMAD LOKAL 12 | AW14: PMAJ LOKAL 24 | AX14: JUN | AY14: GSS LOKAL 40 | AZ14: IIP LOKAL 40 | BA14: IHAG LOKAL 40 | BB14: GPD LOKAL 40 | BC14: CGSS MA (NS) 12 | BD14: PMAD LOKAL 12 | BE14: PMAJ LOKAL 24 | BF14: JUL | BG14: GSS LOKAL 40 | BH14: IIP LOKAL 40 | BI14: IHAG LOKAL 40 | BJ14: GPD LOKAL 40 | BK14: CGSS MA (NS) 12 | BL14: PMAD LOKAL 12 | BM14: PMAJ LOKAL 24 | BN14: AUG | BO14: GSS LOKAL 40 | BP14: IIP LOKAL 40 | BQ14: IHAG LOKAL 40 | BR14: GPD LOKAL 40 | BS14: CGSS MA (NS) 12 | BT14: PMAD LOKAL 12 | BU14: PMAJ LOKAL 24 | BV14: SEP | BW14: GSS LOKAL 40 | BX14: IIP LOKAL 40 | BY14: IHAG LOKAL 40 | BZ14: GPD LOKAL 40 | CA14: CGSS MA (NS) 12 | CB14: PMAD LOKAL 12 | CC14: PMAJ LOKAL 24 | CD14: OCT | CE14: GSS LOKAL 40 | CF14: IIP LOKAL 40 | CG14: IHAG LOKAL 40 | CH14: GPD LOKAL 40 | CI14: CGSS MA (NS) 12 | CJ14: PMAD LOKAL 12 | CK14: PMAJ LOKAL 24 | CL14: NOV | CM14: GSS LOKAL 40 | CN14: IIP LOKAL 40 | CO14: IHAG LOKAL 40 | CP14: GPD LOKAL 40 | CQ14: CGSS MA (NS) 12 | CR14: PMAD LOKAL 12 | CS14: PMAJ LOKAL 24 | CT14: DEC | CU14: GSS LOKAL 40 | CV14: IIP LOKAL 40 | CW14: IHAG LOKAL 40 | CX14: GPD LOKAL 40 | CY14: CGSS MA (NS) 12 | CZ14: PMAD LOKAL 12 | DA14: PMAJ LOKAL 24 | DB14: TOTAL | DC14: YTD
